<p>I am trying to run this very basic code (found at <a href="http://pandas.pydata.org/pandas-docs/stable/remote_data.html#remote-data-ga" rel="nofollow">http://pandas.pydata.org/pandas-docs/stable/remote_data.html#remote-data-ga</a>):</p>  <pre><code>import pandas.io.ga as ga     ga.read_ga(         account_id  = "ZZZZZZZZZZ",         profile_id  = "YYYYYYYYYY",         property_id = "XXXXXXXXX",         metrics     = ['users', 'pageviews'],         dimensions  = ['dayOfWeek'],         start_date  = "2014-01-01",         end_date    = "2014-08-01") </code></pre>  <p>I get the following result:</p>  <pre><code>Traceback (most recent call last):   File "Untitled.py", line 14, in &lt;module&gt;     end_date    = "2015-01-01"  File "C:\Users\gwaldman\AppData\Local\Continuum\Anaconda\lib\sitepackages\pandas\io\ga.py", line 105, in read_gareader = GAnalytics(**reader_kwds)  File "C:\Users\gwaldman\AppData\Local\Continuum\Anaconda\lib\sitepackages\pandas\io\ga.py", line 174, in __init__self._service = self._init_service(secrets) File "C:\Users\gwaldman\AppData\Local\Continuum\Anaconda\lib\sitepackages\pandas\io\ga.py", line 186, in _init_servicehttp = self.authenticate(secrets) File "C:\Users\gwaldman\AppData\Local\Continuum\Anaconda\lib\sitepackages\pandas\io\ga.py", line 146, in authenticate return auth.authenticate(flow, self.token_store) File "C:\Users\gwaldman\AppData\Local\Continuum\Anaconda\lib\sitepackages\pandas\io\auth.py", line 108, in authenticate credentials = tools.run(flow, storage)  AttributeError: 'module' object has no attribute 'run' </code></pre>  <p>I followed the instructions for authenticating with Google APIs, and have been able to do it successfully, but can't seem to get it to work with pandas. I downloaded a client_secrets file and put it in the same folder as pandas.io.ga</p>  <p>I am also running Anaconda Python. Have searched and tried tons of stuff, but cannot seem to even get to authentication.</p>